Traceback (most recent call last):
  File "/scratch/gpfs/mandyl/relative_importance/nlpenv/lib/python3.8/site-packages/urllib3/connection.py", line 159, in _new_conn
    conn = connection.create_connection(
  File "/scratch/gpfs/mandyl/relative_importance/nlpenv/lib/python3.8/site-packages/urllib3/util/connection.py", line 61, in create_connection
    for res in socket.getaddrinfo(host, port, family, socket.SOCK_STREAM):
  File "/usr/licensed/anaconda3/2020.11/lib/python3.8/socket.py", line 918, in getaddrinfo
    for res in _socket.getaddrinfo(host, port, family, type, proto, flags):
socket.gaierror: [Errno -2] Name or service not known

During handling of the above exception, another exception occurred:

Traceback (most recent call last):
  File "/scratch/gpfs/mandyl/relative_importance/nlpenv/lib/python3.8/site-packages/urllib3/connectionpool.py", line 670, in urlopen
    httplib_response = self._make_request(
  File "/scratch/gpfs/mandyl/relative_importance/nlpenv/lib/python3.8/site-packages/urllib3/connectionpool.py", line 381, in _make_request
    self._validate_conn(conn)
  File "/scratch/gpfs/mandyl/relative_importance/nlpenv/lib/python3.8/site-packages/urllib3/connectionpool.py", line 976, in _validate_conn
    conn.connect()
  File "/scratch/gpfs/mandyl/relative_importance/nlpenv/lib/python3.8/site-packages/urllib3/connection.py", line 308, in connect
    conn = self._new_conn()
  File "/scratch/gpfs/mandyl/relative_importance/nlpenv/lib/python3.8/site-packages/urllib3/connection.py", line 171, in _new_conn
    raise NewConnectionError(
urllib3.exceptions.NewConnectionError: <urllib3.connection.HTTPSConnection object at 0x152b2a2f21c0>: Failed to establish a new connection: [Errno -2] Name or service not known

During handling of the above exception, another exception occurred:

Traceback (most recent call last):
  File "/scratch/gpfs/mandyl/relative_importance/nlpenv/lib/python3.8/site-packages/requests/adapters.py", line 439, in send
    resp = conn.urlopen(
  File "/scratch/gpfs/mandyl/relative_importance/nlpenv/lib/python3.8/site-packages/urllib3/connectionpool.py", line 724, in urlopen
    retries = retries.increment(
  File "/scratch/gpfs/mandyl/relative_importance/nlpenv/lib/python3.8/site-packages/urllib3/util/retry.py", line 439, in increment
    raise MaxRetryError(_pool, url, error or ResponseError(cause))
urllib3.exceptions.MaxRetryError: HTTPSConnectionPool(host='raw.githubusercontent.com', port=443): Max retries exceeded with url: /explosion/spacy-models/master/shortcuts-v2.json (Caused by NewConnectionError('<urllib3.connection.HTTPSConnection object at 0x152b2a2f21c0>: Failed to establish a new connection: [Errno -2] Name or service not known'))

During handling of the above exception, another exception occurred:

Traceback (most recent call last):
  File "/usr/licensed/anaconda3/2020.11/lib/python3.8/runpy.py", line 194, in _run_module_as_main
    return _run_code(code, main_globals, None,
  File "/usr/licensed/anaconda3/2020.11/lib/python3.8/runpy.py", line 87, in _run_code
    exec(code, run_globals)
  File "/scratch/gpfs/mandyl/relative_importance/nlpenv/lib/python3.8/site-packages/spacy/__main__.py", line 33, in <module>
    plac.call(commands[command], sys.argv[1:])
  File "/scratch/gpfs/mandyl/relative_importance/nlpenv/lib/python3.8/site-packages/plac_core.py", line 367, in call
    cmd, result = parser.consume(arglist)
  File "/scratch/gpfs/mandyl/relative_importance/nlpenv/lib/python3.8/site-packages/plac_core.py", line 232, in consume
    return cmd, self.func(*(args + varargs + extraopts), **kwargs)
  File "/scratch/gpfs/mandyl/relative_importance/nlpenv/lib/python3.8/site-packages/spacy/cli/download.py", line 44, in download
    shortcuts = get_json(about.__shortcuts__, "available shortcuts")
  File "/scratch/gpfs/mandyl/relative_importance/nlpenv/lib/python3.8/site-packages/spacy/cli/download.py", line 95, in get_json
    r = requests.get(url)
  File "/scratch/gpfs/mandyl/relative_importance/nlpenv/lib/python3.8/site-packages/requests/api.py", line 76, in get
    return request('get', url, params=params, **kwargs)
  File "/scratch/gpfs/mandyl/relative_importance/nlpenv/lib/python3.8/site-packages/requests/api.py", line 61, in request
    return session.request(method=method, url=url, **kwargs)
  File "/scratch/gpfs/mandyl/relative_importance/nlpenv/lib/python3.8/site-packages/requests/sessions.py", line 530, in request
    resp = self.send(prep, **send_kwargs)
  File "/scratch/gpfs/mandyl/relative_importance/nlpenv/lib/python3.8/site-packages/requests/sessions.py", line 643, in send
    r = adapter.send(request, **kwargs)
  File "/scratch/gpfs/mandyl/relative_importance/nlpenv/lib/python3.8/site-packages/requests/adapters.py", line 516, in send
    raise ConnectionError(e, request=request)
requests.exceptions.ConnectionError: HTTPSConnectionPool(host='raw.githubusercontent.com', port=443): Max retries exceeded with url: /explosion/spacy-models/master/shortcuts-v2.json (Caused by NewConnectionError('<urllib3.connection.HTTPSConnection object at 0x152b2a2f21c0>: Failed to establish a new connection: [Errno -2] Name or service not known'))
['photographed', 'with', 'melancholy', 'richness', 'and', 'eloquently', 'performed', 'yet', 'also', 'decidedly', 'uncinematic'] [0.12927632 0.04653439 0.14534014 0.08031247 0.0199455  0.11096657
 0.07753867 0.01728019 0.0680929  0.1469141  0.15779875] [1.15382517e-06 4.90490816e-09 7.31640997e-07 5.40729528e-06
 3.88007976e-09 9.28179717e-01 4.85922816e-07 6.78656234e-08
 2.11034781e-08 4.24999858e-07 7.18119816e-02]
Traceback (most recent call last):
  File "analyze_all.py", line 166, in <module>
    visualize_sentence(i, et_tokens, human_importance, lm_importance, "plots/" + model + "_" + str(i) + ".png")
  File "/scratch/gpfs/mandyl/relative_importance/analysis/create_plots.py", line 168, in visualize_sentence
    human_data = pd.DataFrame({"Tokens": tokens, "Importance": human_saliency[i]})
  File "/scratch/gpfs/mandyl/relative_importance/nlpenv/lib/python3.8/site-packages/pandas/core/frame.py", line 435, in __init__
    mgr = init_dict(data, index, columns, dtype=dtype)
  File "/scratch/gpfs/mandyl/relative_importance/nlpenv/lib/python3.8/site-packages/pandas/core/internals/construction.py", line 254, in init_dict
    return arrays_to_mgr(arrays, data_names, index, columns, dtype=dtype)
  File "/scratch/gpfs/mandyl/relative_importance/nlpenv/lib/python3.8/site-packages/pandas/core/internals/construction.py", line 64, in arrays_to_mgr
    index = extract_index(arrays)
  File "/scratch/gpfs/mandyl/relative_importance/nlpenv/lib/python3.8/site-packages/pandas/core/internals/construction.py", line 365, in extract_index
    raise ValueError("arrays must all be same length")
ValueError: arrays must all be same length
