Traceback (most recent call last):
  File "/scratch/gpfs/mandyl/relative_importance/nlpenv/lib/python3.8/site-packages/urllib3/connection.py", line 159, in _new_conn
    conn = connection.create_connection(
  File "/scratch/gpfs/mandyl/relative_importance/nlpenv/lib/python3.8/site-packages/urllib3/util/connection.py", line 61, in create_connection
    for res in socket.getaddrinfo(host, port, family, socket.SOCK_STREAM):
  File "/usr/licensed/anaconda3/2020.11/lib/python3.8/socket.py", line 918, in getaddrinfo
    for res in _socket.getaddrinfo(host, port, family, type, proto, flags):
socket.gaierror: [Errno -2] Name or service not known

During handling of the above exception, another exception occurred:

Traceback (most recent call last):
  File "/scratch/gpfs/mandyl/relative_importance/nlpenv/lib/python3.8/site-packages/urllib3/connectionpool.py", line 670, in urlopen
    httplib_response = self._make_request(
  File "/scratch/gpfs/mandyl/relative_importance/nlpenv/lib/python3.8/site-packages/urllib3/connectionpool.py", line 381, in _make_request
    self._validate_conn(conn)
  File "/scratch/gpfs/mandyl/relative_importance/nlpenv/lib/python3.8/site-packages/urllib3/connectionpool.py", line 976, in _validate_conn
    conn.connect()
  File "/scratch/gpfs/mandyl/relative_importance/nlpenv/lib/python3.8/site-packages/urllib3/connection.py", line 308, in connect
    conn = self._new_conn()
  File "/scratch/gpfs/mandyl/relative_importance/nlpenv/lib/python3.8/site-packages/urllib3/connection.py", line 171, in _new_conn
    raise NewConnectionError(
urllib3.exceptions.NewConnectionError: <urllib3.connection.HTTPSConnection object at 0x14db17e5d9a0>: Failed to establish a new connection: [Errno -2] Name or service not known

During handling of the above exception, another exception occurred:

Traceback (most recent call last):
  File "/scratch/gpfs/mandyl/relative_importance/nlpenv/lib/python3.8/site-packages/requests/adapters.py", line 439, in send
    resp = conn.urlopen(
  File "/scratch/gpfs/mandyl/relative_importance/nlpenv/lib/python3.8/site-packages/urllib3/connectionpool.py", line 724, in urlopen
    retries = retries.increment(
  File "/scratch/gpfs/mandyl/relative_importance/nlpenv/lib/python3.8/site-packages/urllib3/util/retry.py", line 439, in increment
    raise MaxRetryError(_pool, url, error or ResponseError(cause))
urllib3.exceptions.MaxRetryError: HTTPSConnectionPool(host='raw.githubusercontent.com', port=443): Max retries exceeded with url: /explosion/spacy-models/master/shortcuts-v2.json (Caused by NewConnectionError('<urllib3.connection.HTTPSConnection object at 0x14db17e5d9a0>: Failed to establish a new connection: [Errno -2] Name or service not known'))

During handling of the above exception, another exception occurred:

Traceback (most recent call last):
  File "/usr/licensed/anaconda3/2020.11/lib/python3.8/runpy.py", line 194, in _run_module_as_main
    return _run_code(code, main_globals, None,
  File "/usr/licensed/anaconda3/2020.11/lib/python3.8/runpy.py", line 87, in _run_code
    exec(code, run_globals)
  File "/scratch/gpfs/mandyl/relative_importance/nlpenv/lib/python3.8/site-packages/spacy/__main__.py", line 33, in <module>
    plac.call(commands[command], sys.argv[1:])
  File "/scratch/gpfs/mandyl/relative_importance/nlpenv/lib/python3.8/site-packages/plac_core.py", line 367, in call
    cmd, result = parser.consume(arglist)
  File "/scratch/gpfs/mandyl/relative_importance/nlpenv/lib/python3.8/site-packages/plac_core.py", line 232, in consume
    return cmd, self.func(*(args + varargs + extraopts), **kwargs)
  File "/scratch/gpfs/mandyl/relative_importance/nlpenv/lib/python3.8/site-packages/spacy/cli/download.py", line 44, in download
    shortcuts = get_json(about.__shortcuts__, "available shortcuts")
  File "/scratch/gpfs/mandyl/relative_importance/nlpenv/lib/python3.8/site-packages/spacy/cli/download.py", line 95, in get_json
    r = requests.get(url)
  File "/scratch/gpfs/mandyl/relative_importance/nlpenv/lib/python3.8/site-packages/requests/api.py", line 76, in get
    return request('get', url, params=params, **kwargs)
  File "/scratch/gpfs/mandyl/relative_importance/nlpenv/lib/python3.8/site-packages/requests/api.py", line 61, in request
    return session.request(method=method, url=url, **kwargs)
  File "/scratch/gpfs/mandyl/relative_importance/nlpenv/lib/python3.8/site-packages/requests/sessions.py", line 530, in request
    resp = self.send(prep, **send_kwargs)
  File "/scratch/gpfs/mandyl/relative_importance/nlpenv/lib/python3.8/site-packages/requests/sessions.py", line 643, in send
    r = adapter.send(request, **kwargs)
  File "/scratch/gpfs/mandyl/relative_importance/nlpenv/lib/python3.8/site-packages/requests/adapters.py", line 516, in send
    raise ConnectionError(e, request=request)
requests.exceptions.ConnectionError: HTTPSConnectionPool(host='raw.githubusercontent.com', port=443): Max retries exceeded with url: /explosion/spacy-models/master/shortcuts-v2.json (Caused by NewConnectionError('<urllib3.connection.HTTPSConnection object at 0x14db17e5d9a0>: Failed to establish a new connection: [Errno -2] Name or service not known'))
geco
saliency
Traceback (most recent call last):
  File "analyze_all.py", line 123, in <module>
    lm_tokens, lm_importance = extract_model_importance(corpus, model, importance_type)
  File "analyze_all.py", line 31, in extract_model_importance
    with open(RESULTS_FOLDER + dataset + "_" + model + "_" + importance_type + ".txt", "r") as f:
FileNotFoundError: [Errno 2] No such file or directory: 'results_reproduced/geco_bert_saliency.txt'
